[2019-09-13 14:03:42 -0700] [4579] [CRITICAL] WORKER TIMEOUT (pid:4582)
[2019-09-13 14:22:42 -0700] [4579] [CRITICAL] WORKER TIMEOUT (pid:4609)
[2019-09-13 14:22:43 -0700] [4617] [ERROR] Exception in worker process
Traceback (most recent call last):
  File "//anaconda3/envs/psiturk/lib/python2.7/site-packages/gunicorn/arbiter.py", line 583, in spawn_worker
    worker.init_process()
  File "//anaconda3/envs/psiturk/lib/python2.7/site-packages/gunicorn/workers/base.py", line 129, in init_process
    self.load_wsgi()
  File "//anaconda3/envs/psiturk/lib/python2.7/site-packages/gunicorn/workers/base.py", line 138, in load_wsgi
    self.wsgi = self.app.wsgi()
  File "//anaconda3/envs/psiturk/lib/python2.7/site-packages/gunicorn/app/base.py", line 67, in wsgi
    self.callable = self.load()
  File "//anaconda3/envs/psiturk/lib/python2.7/site-packages/psiturk/experiment_server.py", line 48, in load
    return util.import_app("psiturk.experiment:app")
  File "//anaconda3/envs/psiturk/lib/python2.7/site-packages/gunicorn/util.py", line 350, in import_app
    __import__(module)
  File "//anaconda3/envs/psiturk/lib/python2.7/site-packages/psiturk/experiment.py", line 90, in <module>
    init_db()
  File "//anaconda3/envs/psiturk/lib/python2.7/site-packages/psiturk/db.py", line 39, in init_db
    Base.metadata.create_all(bind=engine)
  File "//anaconda3/envs/psiturk/lib/python2.7/site-packages/sqlalchemy/sql/schema.py", line 4287, in create_all
    ddl.SchemaGenerator, self, checkfirst=checkfirst, tables=tables
  File "//anaconda3/envs/psiturk/lib/python2.7/site-packages/sqlalchemy/engine/base.py", line 2032, in _run_visitor
    with self._optional_conn_ctx_manager(connection) as conn:
  File "//anaconda3/envs/psiturk/lib/python2.7/contextlib.py", line 17, in __enter__
    return self.gen.next()
  File "//anaconda3/envs/psiturk/lib/python2.7/site-packages/sqlalchemy/engine/base.py", line 2024, in _optional_conn_ctx_manager
    with self._contextual_connect() as conn:
  File "//anaconda3/envs/psiturk/lib/python2.7/site-packages/sqlalchemy/engine/base.py", line 2226, in _contextual_connect
    self._wrap_pool_connect(self.pool.connect, None),
  File "//anaconda3/envs/psiturk/lib/python2.7/site-packages/sqlalchemy/engine/base.py", line 2266, in _wrap_pool_connect
    e, dialect, self
  File "//anaconda3/envs/psiturk/lib/python2.7/site-packages/sqlalchemy/engine/base.py", line 1536, in _handle_dbapi_exception_noconnection
    util.raise_from_cause(sqlalchemy_exception, exc_info)
  File "//anaconda3/envs/psiturk/lib/python2.7/site-packages/sqlalchemy/util/compat.py", line 399, in raise_from_cause
    reraise(type(exception), exception, tb=exc_tb, cause=cause)
  File "//anaconda3/envs/psiturk/lib/python2.7/site-packages/sqlalchemy/engine/base.py", line 2262, in _wrap_pool_connect
    return fn()
  File "//anaconda3/envs/psiturk/lib/python2.7/site-packages/sqlalchemy/pool/base.py", line 363, in connect
    return _ConnectionFairy._checkout(self)
  File "//anaconda3/envs/psiturk/lib/python2.7/site-packages/sqlalchemy/pool/base.py", line 760, in _checkout
    fairy = _ConnectionRecord.checkout(pool)
  File "//anaconda3/envs/psiturk/lib/python2.7/site-packages/sqlalchemy/pool/base.py", line 492, in checkout
    rec = pool._do_get()
  File "//anaconda3/envs/psiturk/lib/python2.7/site-packages/sqlalchemy/pool/impl.py", line 139, in _do_get
    self._dec_overflow()
  File "//anaconda3/envs/psiturk/lib/python2.7/site-packages/sqlalchemy/util/langhelpers.py", line 68, in __exit__
    compat.reraise(exc_type, exc_value, exc_tb)
  File "//anaconda3/envs/psiturk/lib/python2.7/site-packages/sqlalchemy/pool/impl.py", line 136, in _do_get
    return self._create_connection()
  File "//anaconda3/envs/psiturk/lib/python2.7/site-packages/sqlalchemy/pool/base.py", line 308, in _create_connection
    return _ConnectionRecord(self)
  File "//anaconda3/envs/psiturk/lib/python2.7/site-packages/sqlalchemy/pool/base.py", line 437, in __init__
    self.__connect(first_connect_check=True)
  File "//anaconda3/envs/psiturk/lib/python2.7/site-packages/sqlalchemy/pool/base.py", line 639, in __connect
    connection = pool._invoke_creator(self)
  File "//anaconda3/envs/psiturk/lib/python2.7/site-packages/sqlalchemy/engine/strategies.py", line 114, in connect
    return dialect.connect(*cargs, **cparams)
  File "//anaconda3/envs/psiturk/lib/python2.7/site-packages/sqlalchemy/engine/default.py", line 451, in connect
    return self.dbapi.connect(*cargs, **cparams)
  File "//anaconda3/envs/psiturk/lib/python2.7/site-packages/psycopg2/__init__.py", line 126, in connect
    conn = _connect(dsn, connection_factory=connection_factory, **kwasync)
OperationalError: (psycopg2.OperationalError) could not translate host name "ec2-54-221-238-248.compute-1.amazonaws.com" to address: nodename nor servname provided, or not known

(Background on this error at: http://sqlalche.me/e/e3q8)
[2019-09-24 14:55:51 -0700] [25753] [CRITICAL] WORKER TIMEOUT (pid:25756)
[2019-09-24 15:29:02 -0700] [25753] [CRITICAL] WORKER TIMEOUT (pid:26100)
[2019-09-24 15:29:03 -0700] [26108] [ERROR] Exception in worker process
Traceback (most recent call last):
  File "//anaconda3/envs/psiturk/lib/python2.7/site-packages/gunicorn/arbiter.py", line 583, in spawn_worker
    worker.init_process()
  File "//anaconda3/envs/psiturk/lib/python2.7/site-packages/gunicorn/workers/base.py", line 129, in init_process
    self.load_wsgi()
  File "//anaconda3/envs/psiturk/lib/python2.7/site-packages/gunicorn/workers/base.py", line 138, in load_wsgi
    self.wsgi = self.app.wsgi()
  File "//anaconda3/envs/psiturk/lib/python2.7/site-packages/gunicorn/app/base.py", line 67, in wsgi
    self.callable = self.load()
  File "//anaconda3/envs/psiturk/lib/python2.7/site-packages/psiturk/experiment_server.py", line 48, in load
    return util.import_app("psiturk.experiment:app")
  File "//anaconda3/envs/psiturk/lib/python2.7/site-packages/gunicorn/util.py", line 350, in import_app
    __import__(module)
  File "//anaconda3/envs/psiturk/lib/python2.7/site-packages/psiturk/experiment.py", line 90, in <module>
    init_db()
  File "//anaconda3/envs/psiturk/lib/python2.7/site-packages/psiturk/db.py", line 39, in init_db
    Base.metadata.create_all(bind=engine)
  File "//anaconda3/envs/psiturk/lib/python2.7/site-packages/sqlalchemy/sql/schema.py", line 4287, in create_all
    ddl.SchemaGenerator, self, checkfirst=checkfirst, tables=tables
  File "//anaconda3/envs/psiturk/lib/python2.7/site-packages/sqlalchemy/engine/base.py", line 2032, in _run_visitor
    with self._optional_conn_ctx_manager(connection) as conn:
  File "//anaconda3/envs/psiturk/lib/python2.7/contextlib.py", line 17, in __enter__
    return self.gen.next()
  File "//anaconda3/envs/psiturk/lib/python2.7/site-packages/sqlalchemy/engine/base.py", line 2024, in _optional_conn_ctx_manager
    with self._contextual_connect() as conn:
  File "//anaconda3/envs/psiturk/lib/python2.7/site-packages/sqlalchemy/engine/base.py", line 2226, in _contextual_connect
    self._wrap_pool_connect(self.pool.connect, None),
  File "//anaconda3/envs/psiturk/lib/python2.7/site-packages/sqlalchemy/engine/base.py", line 2266, in _wrap_pool_connect
    e, dialect, self
  File "//anaconda3/envs/psiturk/lib/python2.7/site-packages/sqlalchemy/engine/base.py", line 1536, in _handle_dbapi_exception_noconnection
    util.raise_from_cause(sqlalchemy_exception, exc_info)
  File "//anaconda3/envs/psiturk/lib/python2.7/site-packages/sqlalchemy/util/compat.py", line 399, in raise_from_cause
    reraise(type(exception), exception, tb=exc_tb, cause=cause)
  File "//anaconda3/envs/psiturk/lib/python2.7/site-packages/sqlalchemy/engine/base.py", line 2262, in _wrap_pool_connect
    return fn()
  File "//anaconda3/envs/psiturk/lib/python2.7/site-packages/sqlalchemy/pool/base.py", line 363, in connect
    return _ConnectionFairy._checkout(self)
  File "//anaconda3/envs/psiturk/lib/python2.7/site-packages/sqlalchemy/pool/base.py", line 760, in _checkout
    fairy = _ConnectionRecord.checkout(pool)
  File "//anaconda3/envs/psiturk/lib/python2.7/site-packages/sqlalchemy/pool/base.py", line 492, in checkout
    rec = pool._do_get()
  File "//anaconda3/envs/psiturk/lib/python2.7/site-packages/sqlalchemy/pool/impl.py", line 139, in _do_get
    self._dec_overflow()
  File "//anaconda3/envs/psiturk/lib/python2.7/site-packages/sqlalchemy/util/langhelpers.py", line 68, in __exit__
    compat.reraise(exc_type, exc_value, exc_tb)
  File "//anaconda3/envs/psiturk/lib/python2.7/site-packages/sqlalchemy/pool/impl.py", line 136, in _do_get
    return self._create_connection()
  File "//anaconda3/envs/psiturk/lib/python2.7/site-packages/sqlalchemy/pool/base.py", line 308, in _create_connection
    return _ConnectionRecord(self)
  File "//anaconda3/envs/psiturk/lib/python2.7/site-packages/sqlalchemy/pool/base.py", line 437, in __init__
    self.__connect(first_connect_check=True)
  File "//anaconda3/envs/psiturk/lib/python2.7/site-packages/sqlalchemy/pool/base.py", line 639, in __connect
    connection = pool._invoke_creator(self)
  File "//anaconda3/envs/psiturk/lib/python2.7/site-packages/sqlalchemy/engine/strategies.py", line 114, in connect
    return dialect.connect(*cargs, **cparams)
  File "//anaconda3/envs/psiturk/lib/python2.7/site-packages/sqlalchemy/engine/default.py", line 451, in connect
    return self.dbapi.connect(*cargs, **cparams)
  File "//anaconda3/envs/psiturk/lib/python2.7/site-packages/psycopg2/__init__.py", line 126, in connect
    conn = _connect(dsn, connection_factory=connection_factory, **kwasync)
OperationalError: (psycopg2.OperationalError) could not translate host name "ec2-174-129-226-234.compute-1.amazonaws.com" to address: nodename nor servname provided, or not known

(Background on this error at: http://sqlalche.me/e/e3q8)
